{"name": "Проверка получения количества заказов \"total_today\" для авторизованного пользователя - нет заказов", "status": "failed", "statusDetails": {"message": "AssertionError: Получено неверное значение ключа \"totalToday\": ожидалось \"0\", получено \"517\"", "trace": "self = <test_get_user_orders.TestGetUserOrders object at 0x104c60f80>\nsetup_user = ({'email': 'zkomvewlej@mail.ru', 'name': 'pcbbzinskp', 'password': 'lndjxgptjk'}, 'Bearer eyJhbGciOiJIUzI1NiIsInR5cCI6...WIyOWVkMjgwMDAxYjQ2MDU2MCIsImlhdCI6MTcyMDA3ODAwMiwiZXhwIjoxNzIwMDc5MjAyfQ.ANR1XiPn14XDvmJ8jOuwWEsVRuBrPv69JNgkz25qCnM')\n\n    @allure.title('Проверка получения количества заказов \"total_today\" для авторизованного пользователя - нет заказов')\n    def test_get_user_orders_total_today_authorized_user_no_orders(self, setup_user):\n        user_data, auth_token = setup_user\n        response = HelpersOnCreateUser.try_to_get_user_orders(auth_token)\n    \n    \n        received_body = HelpersOnCheck.check_success_ok(response)\n>       HelpersOnCheck.check_received_orders_total_today(received_body, 0)\n\ntests/test_get_user_orders.py:100: \n_ _ _ _ _ _ _ _ _ _ _ _ _ _ _ _ _ _ _ _ _ _ _ _ _ _ _ _ _ _ _ _ _ _ _ _ _ _ _ _ _ _ _ _ _ _ _ _ _ _ _ _ _ _ _ _ _ _ _ _ _ _ _ _ _ _ _ _ _ _ _ _ _ _ _ _ _ _ _ _ _ \nhelpers.py:191: in check_received_orders_total_today\n    HelpersOnCheck.check_key_and_value_in_body(received_body, KEYS.TOTAL_TODAY_KEY, amount)\n_ _ _ _ _ _ _ _ _ _ _ _ _ _ _ _ _ _ _ _ _ _ _ _ _ _ _ _ _ _ _ _ _ _ _ _ _ _ _ _ _ _ _ _ _ _ _ _ _ _ _ _ _ _ _ _ _ _ _ _ _ _ _ _ _ _ _ _ _ _ _ _ _ _ _ _ _ _ _ _ _ \n\nresponse_body = {'orders': [], 'success': True, 'total': 91975, 'totalToday': 517}, key = 'totalToday', value = 0\n\n    @staticmethod\n    @allure.step('Проверяем значение ключа в ответе')\n    def check_key_and_value_in_body(response_body, key, value):\n        # проверяем наличие ключа в ответе\n        assert key in response_body, f'В ответе отсутствует ключ \"{key}\", получен ответ: \"{response_body}\"'\n        # проверяем значение ключа в ответе\n        received_value = response_body[key]\n>       assert received_value == value, f'Получено неверное значение ключа \"{key}\": ожидалось \"{value}\", получено \"{received_value}\"'\nE       AssertionError: Получено неверное значение ключа \"totalToday\": ожидалось \"0\", получено \"517\"\n\nhelpers.py:24: AssertionError"}, "steps": [{"name": "Отправляем запрос на получение заказов пользователя", "status": "passed", "steps": [{"name": "Отправляем API-запрос на получение заказов пользователя", "status": "passed", "parameters": [{"name": "headers", "value": "{'Authorization': 'Bearer eyJhbGciOiJIUzI1NiIsInR5cCI6IkpXVCJ9.eyJpZCI6IjY2ODY0ZWIyOWVkMjgwMDAxYjQ2MDU2MCIsImlhdCI6MTcyMDA3ODAwMiwiZXhwIjoxNzIwMDc5MjAyfQ.ANR1XiPn14XDvmJ8jOuwWEsVRuBrPv69JNgkz25qCnM'}"}], "start": 1720078002855, "stop": 1720078003278}], "parameters": [{"name": "auth_token", "value": "'Bearer eyJhbGciOiJIUzI1NiIsInR5cCI6IkpXVCJ9.eyJpZCI6IjY2ODY0ZWIyOWVkMjgwMDAxYjQ2MDU2MCIsImlhdCI6MTcyMDA3ODAwMiwiZXhwIjoxNzIwMDc5MjAyfQ.ANR1XiPn14XDvmJ8jOuwWEsVRuBrPv69JNgkz25qCnM'"}], "start": 1720078002855, "stop": 1720078003278}, {"name": "Проверяем, что запрос выполнен успешно", "status": "passed", "steps": [{"name": "Проверяем код ответа", "status": "passed", "parameters": [{"name": "response", "value": "<Response [200]>"}, {"name": "expected_code", "value": "200"}], "start": 1720078003278, "stop": 1720078003279}, {"name": "Проверяем значение поля \"success\" в ответе", "status": "passed", "parameters": [{"name": "response", "value": "<Response [200]>"}, {"name": "expected_value", "value": "True"}], "start": 1720078003279, "stop": 1720078003279}], "parameters": [{"name": "response", "value": "<Response [200]>"}], "start": 1720078003278, "stop": 1720078003279}, {"name": "Проверяем в полученном ответе поле \"totalToday\"", "status": "failed", "statusDetails": {"message": "AssertionError: Получено неверное значение ключа \"totalToday\": ожидалось \"0\", получено \"517\"\n", "trace": "  File \"/Library/Frameworks/Python.framework/Versions/3.12/lib/python3.12/site-packages/allure_commons/_allure.py\", line 192, in impl\n    return func(*a, **kw)\n           ^^^^^^^^^^^^^^\n  File \"/Users/lapka/Downloads/Diplom_3/helpers.py\", line 191, in check_received_orders_total_today\n    HelpersOnCheck.check_key_and_value_in_body(received_body, KEYS.TOTAL_TODAY_KEY, amount)\n  File \"/Library/Frameworks/Python.framework/Versions/3.12/lib/python3.12/site-packages/allure_commons/_allure.py\", line 192, in impl\n    return func(*a, **kw)\n           ^^^^^^^^^^^^^^\n  File \"/Users/lapka/Downloads/Diplom_3/helpers.py\", line 24, in check_key_and_value_in_body\n    assert received_value == value, f'Получено неверное значение ключа \"{key}\": ожидалось \"{value}\", получено \"{received_value}\"'\n"}, "steps": [{"name": "Проверяем значение ключа в ответе", "status": "failed", "statusDetails": {"message": "AssertionError: Получено неверное значение ключа \"totalToday\": ожидалось \"0\", получено \"517\"\n", "trace": "  File \"/Library/Frameworks/Python.framework/Versions/3.12/lib/python3.12/site-packages/allure_commons/_allure.py\", line 192, in impl\n    return func(*a, **kw)\n           ^^^^^^^^^^^^^^\n  File \"/Users/lapka/Downloads/Diplom_3/helpers.py\", line 24, in check_key_and_value_in_body\n    assert received_value == value, f'Получено неверное значение ключа \"{key}\": ожидалось \"{value}\", получено \"{received_value}\"'\n"}, "parameters": [{"name": "response_body", "value": "{'success': True, 'orders': [], 'total': 91975, 'totalToday': 517}"}, {"name": "key", "value": "'totalToday'"}, {"name": "value", "value": "0"}], "start": 1720078003279, "stop": 1720078003279}], "parameters": [{"name": "received_body", "value": "{'success': True, 'orders': [], 'total': 91975, 'totalToday': 517}"}, {"name": "amount", "value": "0"}], "start": 1720078003279, "stop": 1720078003280}], "start": 1720078002855, "stop": 1720078003281, "uuid": "52da9288-0134-4859-bd15-c7d5c934889f", "historyId": "d1c4fb63054bbb1d0f6836206b0adf8f", "testCaseId": "d1c4fb63054bbb1d0f6836206b0adf8f", "fullName": "tests.test_get_user_orders.TestGetUserOrders#test_get_user_orders_total_today_authorized_user_no_orders", "labels": [{"name": "tag", "value": "@pytest.mark.usefixtures('setup_ingredients', scope='class')"}, {"name": "parentSuite", "value": "tests"}, {"name": "suite", "value": "test_get_user_orders"}, {"name": "subSuite", "value": "TestGetUserOrders"}, {"name": "host", "value": "MacBook-Air-Lapka.local"}, {"name": "thread", "value": "7394-MainThread"}, {"name": "framework", "value": "pytest"}, {"name": "language", "value": "cpython3"}, {"name": "package", "value": "tests.test_get_user_orders"}]}